2025-04-27 03:47:13,313 - KitchnSpy - INFO - Application started
2025-04-27 03:47:15,883 - KitchnSpy - INFO - Request started | GET /
2025-04-27 03:47:15,888 - KitchnSpy - INFO - Request completed | Status: 404 | Time: 0.003s
2025-04-27 03:47:16,183 - KitchnSpy - INFO - Request started | GET /favicon.ico
2025-04-27 03:47:16,189 - KitchnSpy - INFO - Request completed | Status: 404 | Time: 0.001s
2025-04-27 03:47:22,096 - KitchnSpy - INFO - Request started | GET /docs
2025-04-27 03:47:22,098 - KitchnSpy - INFO - Request completed | Status: 200 | Time: 0.001s
2025-04-27 03:47:22,405 - KitchnSpy - INFO - Request started | GET /openapi.json
2025-04-27 03:47:22,415 - KitchnSpy - INFO - Request completed | Status: 200 | Time: 0.008s
2025-04-27 03:50:07,619 - KitchnSpy - INFO - Request started | GET /api/v1/products/
2025-04-27 03:50:07,682 - KitchnSpy - INFO - Request completed | Status: 200 | Time: 0.062s
2025-04-27 03:50:30,069 - KitchnSpy - INFO - Request started | DELETE /api/v1/products/680afd372f8cf00cdcb286ed
2025-04-27 03:50:30,218 - KitchnSpy - ERROR - Exception | [TypeError("'DeleteResult' object is not iterable"), TypeError('vars() argument must have __dict__ attribute')]
Traceback (most recent call last):
  File "C:\Users\dell\AppData\Local\Programs\Python\Python312\Lib\site-packages\fastapi\encoders.py", line 324, in jsonable_encoder
    data = dict(obj)
           ^^^^^^^^^
TypeError: 'DeleteResult' object is not iterable

During handling of the above exception, another exception occurred:

Traceback (most recent call last):
  File "C:\Users\dell\AppData\Local\Programs\Python\Python312\Lib\site-packages\fastapi\encoders.py", line 329, in jsonable_encoder
    data = vars(obj)
           ^^^^^^^^^
TypeError: vars() argument must have __dict__ attribute

The above exception was the direct cause of the following exception:

Traceback (most recent call last):
  File "C:\Users\dell\Desktop\Engineering\Projects\KitchnSpy\app\infra\middleware.py", line 23, in dispatch
    response = await call_next(request)
               ^^^^^^^^^^^^^^^^^^^^^^^^
  File "C:\Users\dell\AppData\Local\Programs\Python\Python312\Lib\site-packages\starlette\middleware\base.py", line 163, in call_next
    raise app_exc
  File "C:\Users\dell\AppData\Local\Programs\Python\Python312\Lib\site-packages\starlette\middleware\base.py", line 149, in coro
    await self.app(scope, receive_or_disconnect, send_no_error)
  File "C:\Users\dell\AppData\Local\Programs\Python\Python312\Lib\site-packages\starlette\middleware\exceptions.py", line 62, in __call__
    await wrap_app_handling_exceptions(self.app, conn)(scope, receive, send)
  File "C:\Users\dell\AppData\Local\Programs\Python\Python312\Lib\site-packages\starlette\_exception_handler.py", line 53, in wrapped_app
    raise exc
  File "C:\Users\dell\AppData\Local\Programs\Python\Python312\Lib\site-packages\starlette\_exception_handler.py", line 42, in wrapped_app
    await app(scope, receive, sender)
  File "C:\Users\dell\AppData\Local\Programs\Python\Python312\Lib\site-packages\starlette\routing.py", line 715, in __call__
    await self.middleware_stack(scope, receive, send)
  File "C:\Users\dell\AppData\Local\Programs\Python\Python312\Lib\site-packages\starlette\routing.py", line 735, in app
    await route.handle(scope, receive, send)
  File "C:\Users\dell\AppData\Local\Programs\Python\Python312\Lib\site-packages\starlette\routing.py", line 288, in handle
    await self.app(scope, receive, send)
  File "C:\Users\dell\AppData\Local\Programs\Python\Python312\Lib\site-packages\starlette\routing.py", line 76, in app
    await wrap_app_handling_exceptions(app, request)(scope, receive, send)
  File "C:\Users\dell\AppData\Local\Programs\Python\Python312\Lib\site-packages\starlette\_exception_handler.py", line 53, in wrapped_app
    raise exc
  File "C:\Users\dell\AppData\Local\Programs\Python\Python312\Lib\site-packages\starlette\_exception_handler.py", line 42, in wrapped_app
    await app(scope, receive, sender)
  File "C:\Users\dell\AppData\Local\Programs\Python\Python312\Lib\site-packages\starlette\routing.py", line 73, in app
    response = await f(request)
               ^^^^^^^^^^^^^^^^
  File "C:\Users\dell\AppData\Local\Programs\Python\Python312\Lib\site-packages\fastapi\routing.py", line 327, in app
    content = await serialize_response(
              ^^^^^^^^^^^^^^^^^^^^^^^^^
  File "C:\Users\dell\AppData\Local\Programs\Python\Python312\Lib\site-packages\fastapi\routing.py", line 201, in serialize_response
    return jsonable_encoder(response_content)
           ^^^^^^^^^^^^^^^^^^^^^^^^^^^^^^^^^^
  File "C:\Users\dell\AppData\Local\Programs\Python\Python312\Lib\site-packages\fastapi\encoders.py", line 332, in jsonable_encoder
    raise ValueError(errors) from e
ValueError: [TypeError("'DeleteResult' object is not iterable"), TypeError('vars() argument must have __dict__ attribute')]
2025-04-27 03:50:30,250 - KitchnSpy - ERROR - Unhandled exception | [TypeError("'DeleteResult' object is not iterable"), TypeError('vars() argument must have __dict__ attribute')]
Traceback (most recent call last):
  File "C:\Users\dell\AppData\Local\Programs\Python\Python312\Lib\site-packages\fastapi\encoders.py", line 324, in jsonable_encoder
    data = dict(obj)
           ^^^^^^^^^
TypeError: 'DeleteResult' object is not iterable

During handling of the above exception, another exception occurred:

Traceback (most recent call last):
  File "C:\Users\dell\AppData\Local\Programs\Python\Python312\Lib\site-packages\fastapi\encoders.py", line 329, in jsonable_encoder
    data = vars(obj)
           ^^^^^^^^^
TypeError: vars() argument must have __dict__ attribute

The above exception was the direct cause of the following exception:

Traceback (most recent call last):
  File "C:\Users\dell\Desktop\Engineering\Projects\KitchnSpy\app\infra\middleware.py", line 23, in dispatch
    response = await call_next(request)
               ^^^^^^^^^^^^^^^^^^^^^^^^
  File "C:\Users\dell\AppData\Local\Programs\Python\Python312\Lib\site-packages\starlette\middleware\base.py", line 163, in call_next
    raise app_exc
  File "C:\Users\dell\AppData\Local\Programs\Python\Python312\Lib\site-packages\starlette\middleware\base.py", line 149, in coro
    await self.app(scope, receive_or_disconnect, send_no_error)
  File "C:\Users\dell\AppData\Local\Programs\Python\Python312\Lib\site-packages\starlette\middleware\exceptions.py", line 62, in __call__
    await wrap_app_handling_exceptions(self.app, conn)(scope, receive, send)
  File "C:\Users\dell\AppData\Local\Programs\Python\Python312\Lib\site-packages\starlette\_exception_handler.py", line 53, in wrapped_app
    raise exc
  File "C:\Users\dell\AppData\Local\Programs\Python\Python312\Lib\site-packages\starlette\_exception_handler.py", line 42, in wrapped_app
    await app(scope, receive, sender)
  File "C:\Users\dell\AppData\Local\Programs\Python\Python312\Lib\site-packages\starlette\routing.py", line 715, in __call__
    await self.middleware_stack(scope, receive, send)
  File "C:\Users\dell\AppData\Local\Programs\Python\Python312\Lib\site-packages\starlette\routing.py", line 735, in app
    await route.handle(scope, receive, send)
  File "C:\Users\dell\AppData\Local\Programs\Python\Python312\Lib\site-packages\starlette\routing.py", line 288, in handle
    await self.app(scope, receive, send)
  File "C:\Users\dell\AppData\Local\Programs\Python\Python312\Lib\site-packages\starlette\routing.py", line 76, in app
    await wrap_app_handling_exceptions(app, request)(scope, receive, send)
  File "C:\Users\dell\AppData\Local\Programs\Python\Python312\Lib\site-packages\starlette\_exception_handler.py", line 53, in wrapped_app
    raise exc
  File "C:\Users\dell\AppData\Local\Programs\Python\Python312\Lib\site-packages\starlette\_exception_handler.py", line 42, in wrapped_app
    await app(scope, receive, sender)
  File "C:\Users\dell\AppData\Local\Programs\Python\Python312\Lib\site-packages\starlette\routing.py", line 73, in app
    response = await f(request)
               ^^^^^^^^^^^^^^^^
  File "C:\Users\dell\AppData\Local\Programs\Python\Python312\Lib\site-packages\fastapi\routing.py", line 327, in app
    content = await serialize_response(
              ^^^^^^^^^^^^^^^^^^^^^^^^^
  File "C:\Users\dell\AppData\Local\Programs\Python\Python312\Lib\site-packages\fastapi\routing.py", line 201, in serialize_response
    return jsonable_encoder(response_content)
           ^^^^^^^^^^^^^^^^^^^^^^^^^^^^^^^^^^
  File "C:\Users\dell\AppData\Local\Programs\Python\Python312\Lib\site-packages\fastapi\encoders.py", line 332, in jsonable_encoder
    raise ValueError(errors) from e
ValueError: [TypeError("'DeleteResult' object is not iterable"), TypeError('vars() argument must have __dict__ attribute')]
2025-04-27 04:50:34,350 - KitchnSpy - INFO - Request started | GET /docs
2025-04-27 04:50:34,352 - KitchnSpy - INFO - Request completed | Status: 200 | Time: 0.001s
2025-04-27 04:50:34,563 - KitchnSpy - INFO - Request started | GET /openapi.json
2025-04-27 04:50:34,565 - KitchnSpy - INFO - Request completed | Status: 200 | Time: 0.001s
2025-04-27 04:50:43,704 - KitchnSpy - INFO - Request started | DELETE /api/v1/products/680afd372f8cf00cdcb286ed
2025-04-27 04:50:43,752 - KitchnSpy - ERROR - Exception | [TypeError("'DeleteResult' object is not iterable"), TypeError('vars() argument must have __dict__ attribute')]
Traceback (most recent call last):
  File "C:\Users\dell\AppData\Local\Programs\Python\Python312\Lib\site-packages\fastapi\encoders.py", line 324, in jsonable_encoder
    data = dict(obj)
           ^^^^^^^^^
TypeError: 'DeleteResult' object is not iterable

During handling of the above exception, another exception occurred:

Traceback (most recent call last):
  File "C:\Users\dell\AppData\Local\Programs\Python\Python312\Lib\site-packages\fastapi\encoders.py", line 329, in jsonable_encoder
    data = vars(obj)
           ^^^^^^^^^
TypeError: vars() argument must have __dict__ attribute

The above exception was the direct cause of the following exception:

Traceback (most recent call last):
  File "C:\Users\dell\Desktop\Engineering\Projects\KitchnSpy\app\infra\middleware.py", line 23, in dispatch
    response = await call_next(request)
               ^^^^^^^^^^^^^^^^^^^^^^^^
  File "C:\Users\dell\AppData\Local\Programs\Python\Python312\Lib\site-packages\starlette\middleware\base.py", line 163, in call_next
    raise app_exc
  File "C:\Users\dell\AppData\Local\Programs\Python\Python312\Lib\site-packages\starlette\middleware\base.py", line 149, in coro
    await self.app(scope, receive_or_disconnect, send_no_error)
  File "C:\Users\dell\AppData\Local\Programs\Python\Python312\Lib\site-packages\starlette\middleware\exceptions.py", line 62, in __call__
    await wrap_app_handling_exceptions(self.app, conn)(scope, receive, send)
  File "C:\Users\dell\AppData\Local\Programs\Python\Python312\Lib\site-packages\starlette\_exception_handler.py", line 53, in wrapped_app
    raise exc
  File "C:\Users\dell\AppData\Local\Programs\Python\Python312\Lib\site-packages\starlette\_exception_handler.py", line 42, in wrapped_app
    await app(scope, receive, sender)
  File "C:\Users\dell\AppData\Local\Programs\Python\Python312\Lib\site-packages\starlette\routing.py", line 715, in __call__
    await self.middleware_stack(scope, receive, send)
  File "C:\Users\dell\AppData\Local\Programs\Python\Python312\Lib\site-packages\starlette\routing.py", line 735, in app
    await route.handle(scope, receive, send)
  File "C:\Users\dell\AppData\Local\Programs\Python\Python312\Lib\site-packages\starlette\routing.py", line 288, in handle
    await self.app(scope, receive, send)
  File "C:\Users\dell\AppData\Local\Programs\Python\Python312\Lib\site-packages\starlette\routing.py", line 76, in app
    await wrap_app_handling_exceptions(app, request)(scope, receive, send)
  File "C:\Users\dell\AppData\Local\Programs\Python\Python312\Lib\site-packages\starlette\_exception_handler.py", line 53, in wrapped_app
    raise exc
  File "C:\Users\dell\AppData\Local\Programs\Python\Python312\Lib\site-packages\starlette\_exception_handler.py", line 42, in wrapped_app
    await app(scope, receive, sender)
  File "C:\Users\dell\AppData\Local\Programs\Python\Python312\Lib\site-packages\starlette\routing.py", line 73, in app
    response = await f(request)
               ^^^^^^^^^^^^^^^^
  File "C:\Users\dell\AppData\Local\Programs\Python\Python312\Lib\site-packages\fastapi\routing.py", line 327, in app
    content = await serialize_response(
              ^^^^^^^^^^^^^^^^^^^^^^^^^
  File "C:\Users\dell\AppData\Local\Programs\Python\Python312\Lib\site-packages\fastapi\routing.py", line 201, in serialize_response
    return jsonable_encoder(response_content)
           ^^^^^^^^^^^^^^^^^^^^^^^^^^^^^^^^^^
  File "C:\Users\dell\AppData\Local\Programs\Python\Python312\Lib\site-packages\fastapi\encoders.py", line 332, in jsonable_encoder
    raise ValueError(errors) from e
ValueError: [TypeError("'DeleteResult' object is not iterable"), TypeError('vars() argument must have __dict__ attribute')]
2025-04-27 04:50:43,754 - KitchnSpy - ERROR - Unhandled exception | [TypeError("'DeleteResult' object is not iterable"), TypeError('vars() argument must have __dict__ attribute')]
Traceback (most recent call last):
  File "C:\Users\dell\AppData\Local\Programs\Python\Python312\Lib\site-packages\fastapi\encoders.py", line 324, in jsonable_encoder
    data = dict(obj)
           ^^^^^^^^^
TypeError: 'DeleteResult' object is not iterable

During handling of the above exception, another exception occurred:

Traceback (most recent call last):
  File "C:\Users\dell\AppData\Local\Programs\Python\Python312\Lib\site-packages\fastapi\encoders.py", line 329, in jsonable_encoder
    data = vars(obj)
           ^^^^^^^^^
TypeError: vars() argument must have __dict__ attribute

The above exception was the direct cause of the following exception:

Traceback (most recent call last):
  File "C:\Users\dell\Desktop\Engineering\Projects\KitchnSpy\app\infra\middleware.py", line 23, in dispatch
    response = await call_next(request)
               ^^^^^^^^^^^^^^^^^^^^^^^^
  File "C:\Users\dell\AppData\Local\Programs\Python\Python312\Lib\site-packages\starlette\middleware\base.py", line 163, in call_next
    raise app_exc
  File "C:\Users\dell\AppData\Local\Programs\Python\Python312\Lib\site-packages\starlette\middleware\base.py", line 149, in coro
    await self.app(scope, receive_or_disconnect, send_no_error)
  File "C:\Users\dell\AppData\Local\Programs\Python\Python312\Lib\site-packages\starlette\middleware\exceptions.py", line 62, in __call__
    await wrap_app_handling_exceptions(self.app, conn)(scope, receive, send)
  File "C:\Users\dell\AppData\Local\Programs\Python\Python312\Lib\site-packages\starlette\_exception_handler.py", line 53, in wrapped_app
    raise exc
  File "C:\Users\dell\AppData\Local\Programs\Python\Python312\Lib\site-packages\starlette\_exception_handler.py", line 42, in wrapped_app
    await app(scope, receive, sender)
  File "C:\Users\dell\AppData\Local\Programs\Python\Python312\Lib\site-packages\starlette\routing.py", line 715, in __call__
    await self.middleware_stack(scope, receive, send)
  File "C:\Users\dell\AppData\Local\Programs\Python\Python312\Lib\site-packages\starlette\routing.py", line 735, in app
    await route.handle(scope, receive, send)
  File "C:\Users\dell\AppData\Local\Programs\Python\Python312\Lib\site-packages\starlette\routing.py", line 288, in handle
    await self.app(scope, receive, send)
  File "C:\Users\dell\AppData\Local\Programs\Python\Python312\Lib\site-packages\starlette\routing.py", line 76, in app
    await wrap_app_handling_exceptions(app, request)(scope, receive, send)
  File "C:\Users\dell\AppData\Local\Programs\Python\Python312\Lib\site-packages\starlette\_exception_handler.py", line 53, in wrapped_app
    raise exc
  File "C:\Users\dell\AppData\Local\Programs\Python\Python312\Lib\site-packages\starlette\_exception_handler.py", line 42, in wrapped_app
    await app(scope, receive, sender)
  File "C:\Users\dell\AppData\Local\Programs\Python\Python312\Lib\site-packages\starlette\routing.py", line 73, in app
    response = await f(request)
               ^^^^^^^^^^^^^^^^
  File "C:\Users\dell\AppData\Local\Programs\Python\Python312\Lib\site-packages\fastapi\routing.py", line 327, in app
    content = await serialize_response(
              ^^^^^^^^^^^^^^^^^^^^^^^^^
  File "C:\Users\dell\AppData\Local\Programs\Python\Python312\Lib\site-packages\fastapi\routing.py", line 201, in serialize_response
    return jsonable_encoder(response_content)
           ^^^^^^^^^^^^^^^^^^^^^^^^^^^^^^^^^^
  File "C:\Users\dell\AppData\Local\Programs\Python\Python312\Lib\site-packages\fastapi\encoders.py", line 332, in jsonable_encoder
    raise ValueError(errors) from e
ValueError: [TypeError("'DeleteResult' object is not iterable"), TypeError('vars() argument must have __dict__ attribute')]
